<?xml version='1.0' encoding='UTF-8'?>
<mujoco model="ur3">
  <compiler angle="radian"/>

  <asset>
    <mesh name="base" file="base.stl"/>
    <mesh name="shoulder" file="shoulder.stl"/>
    <mesh name="upperarm" file="upperarm.stl"/>
    <mesh name="forearm" file="forearm.stl"/>
    <mesh name="wrist1" file="wrist1.stl"/>
    <mesh name="wrist2" file="wrist2.stl"/>
    <mesh name="wrist3" file="wrist3.stl"/>
  </asset>

  <worldbody>
    <geom type="mesh" rgba="0.7 0.7 0.7 1" mesh="base"/>
    <body name="shoulder_link" pos="0 0 0.1519">
      <inertial pos="0 0 0" mass="2.2" diaginertia="0.009711792 0.009711792 0.00675"/>
      <joint name="shoulder_pan_joint" pos="0 0 0" axis="0 0 1" range="-6.28319 6.28319" actuatorfrcrange="-330 330" armature="1e-06"/>
      <geom type="mesh" rgba="0.7 0.7 0.7 1" mesh="shoulder"/>
      <body name="upper_arm_link" pos="0 0.1198 0" quat="0.707107 0 0.707107 0">
        <inertial pos="0 0 0.121825" mass="3.762" diaginertia="0.026074200000000002 0.026074200000000002 0.0115425"/>
        <joint name="shoulder_lift_joint" pos="0 0 0" axis="0 1 0" range="-6.28319 6.28319" actuatorfrcrange="-330 330" armature="1e-06"/>
        <geom type="mesh" rgba="0.7 0.7 0.7 1" mesh="upperarm"/>
        <body name="forearm_link" pos="0 -0.0925 0.24365">
          <inertial pos="0 0 0.106625" mass="1.3860000000000001" diaginertia="0.007856172 0.007856172 0.0042525"/>
          <joint name="elbow_joint" pos="0 0 0" axis="0 1 0" range="-3.14159 3.14159" actuatorfrcrange="-150 150" armature="1e-06"/>
          <geom type="mesh" rgba="0.7 0.7 0.7 1" mesh="forearm"/>
          <body name="wrist_1_link" pos="0 0 0.21325" quat="0.707107 0 0.707107 0">
            <inertial pos="0 0 0" quat="0.5 0.5 -0.5 0.5" mass="0.8800000000000001" diaginertia="0.0026999999999999997 0.002502 0.002502"/>
            <joint name="wrist_1_joint" pos="0 0 0" axis="0 1 0" range="-6.28319 6.28319" actuatorfrcrange="-54 54" armature="1e-06"/>
            <geom type="mesh" rgba="0.7 0.7 0.7 1" mesh="wrist1"/>
            <body name="wrist_2_link" pos="0 0.08505 0">
              <inertial pos="0 0 0" quat="0.5 0.5 -0.5 0.5" mass="0.8800000000000001" diaginertia="0.0026999999999999997 0.002502 0.002502"/>
              <joint name="wrist_2_joint" pos="0 0 0" axis="0 0 1" range="-6.28319 6.28319" actuatorfrcrange="-54 54" armature="1e-06"/>
              <geom type="mesh" rgba="0.7 0.7 0.7 1" mesh="wrist2"/>
              <body name="wrist_3_link" pos="0 0 0.08535">
                <inertial pos="0 0.000204843 0" quat="0.5 0.5 -0.5 0.5" mass="0.3861" diaginertia="0.0011874563999999998 0.0011008308 0.0010946448"/>
                <joint name="wrist_3_joint" pos="0 0 0" axis="0 1 0" range="-6.28319 6.28319" actuatorfrcrange="-54 54" armature="1e-06"/>
                <geom type="mesh" rgba="0.7 0.7 0.7 1" mesh="wrist3"/>
                <geom size="0.005 0.005 0.005" pos="0 0.0719 0" quat="0.707107 0 0 0.707107" type="box"/>
              </body>
            </body>
          </body>
        </body>
      </body>
    </body>
  </worldbody>
<actuator><motor name="shoulder_pan_joint_motor" joint="shoulder_pan_joint" ctrlrange="-100 100"/><motor name="shoulder_lift_joint_motor" joint="shoulder_lift_joint" ctrlrange="-100 100"/><motor name="elbow_joint_motor" joint="elbow_joint" ctrlrange="-100 100"/><motor name="wrist_1_joint_motor" joint="wrist_1_joint" ctrlrange="-100 100"/><motor name="wrist_2_joint_motor" joint="wrist_2_joint" ctrlrange="-100 100"/><motor name="wrist_3_joint_motor" joint="wrist_3_joint" ctrlrange="-100 100"/></actuator></mujoco>
